#VRML_SIM R2023b utf8

EXTERNPROTO "https://raw.githubusercontent.com/cyberbotics/webots/R2022b/projects/objects/floors/protos/RectangleArena.proto"
EXTERNPROTO "https://raw.githubusercontent.com/cyberbotics/webots/R2022b/projects/objects/backgrounds/protos/TexturedBackground.proto"
EXTERNPROTO "https://raw.githubusercontent.com/cyberbotics/webots/R2022b/projects/objects/backgrounds/protos/TexturedBackgroundLight.proto"
EXTERNPROTO "https://raw.githubusercontent.com/cyberbotics/webots/R2022b/projects/objects/apartment_structure/protos/Wall.proto"

WorldInfo {
}
Viewpoint {
  orientation -0.5773502691896258 0.5773502691896258 0.5773502691896258 2.0944
  position 0.9052265143373529 0.06526260340254164 24.21986303186496
}
Wall {
  translation 0 2.5 0
  rotation -1 0 0 -5.307179586466759e-06
  size 6 0.1 1
}
TexturedBackground {
}
TexturedBackgroundLight {
  castShadows FALSE
}
RectangleArena {
  floorSize 10 10
  floorTileSize 2 2
  wallHeight 0.3
}
Solid {
  translation 2 -2.5 0
  children [
    Shape {
      appearance PBRAppearance {
        baseColor 0 0 0
      }
      geometry Cylinder {
        height 0.01
        radius 0.12
      }
    }
  ]
}
Wall {
  translation 1 -1 0
  rotation -1 0 0 -5.307179586466759e-06
  name "wall(2)"
  size 0.1 3 1
}
Wall {
  translation 3 0 0
  rotation -1 0 0 -5.307179586466759e-06
  name "wall(4)"
  size 0.1 5 1
}
Wall {
  translation -1 -1 0
  rotation -1 0 0 -5.307179586466759e-06
  name "wall(5)"
  size 0.1 3 1
}
Wall {
  translation -3 0 0
  rotation -1 0 0 -5.307179586466759e-06
  name "wall(3)"
  size 0.1 5 1
}
Wall {
  translation 0 0.5 0
  rotation -0.8944271909999159 0.4472135954999579 0 -5.307179586466759e-06
  name "wall(1)"
  size 2 0.1 1
}
Wall {
  translation 1.5 -0.5 -1.18697e-06
  rotation -0.8944271909999159 0.4472135954999579 0 -5.307179586466759e-06
  name "wall(8)"
  size 1 0.1 1
}
Wall {
  translation 2.5 -1.5 -3.56047e-06
  rotation -0.8944271909999159 0.4472135954999579 0 -5.307179586466759e-06
  name "wall(9)"
  size 1 0.1 1
}
Wall {
  translation 2.5 0.5 5.93342e-06
  rotation -0.8944271909999159 0.4472135954999579 0 -5.307179586466759e-06
  name "wall(7)"
  size 1 0.1 1
}
Wall {
  translation -2 -2.5 0
  rotation -1 0 0 -5.307179586466759e-06
  name "wall(6)"
  size 2 0.1 1
}
Robot {
  translation -2 -2 0.0163082
  rotation 0 0 0.9999999999999999 -3.0537953071795862
  children [
    DEF Body Pose {
      translation 0 0 0.11
      children [
        Shape {
          appearance PBRAppearance {
            baseColor 0 0 1
            roughness 1
          }
          geometry Cylinder {
            height 0.2
            radius 0.15
          }
        }
      ]
      translationStep 0
      rotationStep 0
    }
    HingeJoint {
      jointParameters HingeJointParameters {
        position -3117.2045323575717
        anchor 0.15 0 0.05
      }
      device [
        RotationalMotor {
          name "motor1"
        }
      ]
      endPoint Solid {
        translation 0.14103535773023002 0.00028949826568602907 0.049850300464676235
        rotation 0.5688127091481104 0.6133208521158678 0.5479868924266827 2.050385889270344
        children [
          DEF wheel Shape {
            appearance PBRAppearance {
              baseColor 0.1 0.1 0.1
              roughness 1
              metalness 0
            }
            geometry Cylinder {
              height 0.02
              radius 0.05
            }
          }
        ]
        boundingObject USE wheel
        physics Physics {
        }
      }
    }
    HingeJoint {
      jointParameters HingeJointParameters {
        position 8854.552422463155
        anchor -0.15 0 0.05
      }
      device [
        RotationalMotor {
          name "motor2"
        }
      ]
      endPoint Solid {
        translation -0.14108997401484236 -4.9539049434897054e-05 0.04985572324596037
        rotation 0.7027654545845371 0.10188596634940812 0.7040880383188144 2.9531912833334193
        children [
          USE wheel
        ]
        name "solid(1)"
        boundingObject USE wheel
        physics Physics {
        }
      }
    }
    DEF Front Solid {
      translation 0 -0.13 0.21
      children [
        Shape {
          appearance PBRAppearance {
            roughness 1
          }
          geometry Box {
            size 0.02 0.04 0.01
          }
        }
      ]
      name "front"
    }
    Solid {
      translation 0.1 0.1 0.21
      rotation 0 1 0 0
      children [
        DistanceSensor {
          rotation 0 0 1 0.7854003061004253
          name "distance sensor_E_2"
          lookupTable [
            0 0 0
            3 3 0
          ]
          aperture 1
          gaussianWidth 1.57
        }
        Shape {
          geometry Cylinder {
            height 0.01
            radius 0.01
          }
        }
      ]
      name "Sensor_E_2"
    }
    Solid {
      translation -0.1 0.1 0.21
      children [
        DistanceSensor {
          rotation 0 0 1 2.3562
          name "distance sensor_D_2"
          lookupTable [
            0 0 0
            3 3 0
          ]
          aperture 1
          gaussianWidth 1.5697
        }
        Shape {
          geometry Cylinder {
            height 0.01
            radius 0.01
          }
        }
      ]
      name "Sensor_D_2"
    }
    Solid {
      translation -0.1 -0.1 0.21
      children [
        DistanceSensor {
          rotation 0 0 1 -2.355
          name "distance sensor_D_1"
          lookupTable [
            0 0 0
            3 3 0
          ]
          aperture 1
          gaussianWidth 1.57
        }
        Shape {
          geometry Cylinder {
            height 0.01
            radius 0.01
          }
        }
      ]
      name "Sensor_D_1"
    }
    Solid {
      translation 0.1 -0.1 0.21
      children [
        DistanceSensor {
          rotation 0 0 1 -0.7854
          name "distance sensor_E_1"
          lookupTable [
            0 0 0
            3 3 0
          ]
          aperture 1
          gaussianWidth 1.57
        }
        Shape {
          geometry Cylinder {
            height 0.01
            radius 0.01
          }
        }
      ]
      name "Sensor_E_1"
    }
    Solid {
      translation 1.26827e-08 4.42916e-09 0.21
      rotation 0 0 1 3.14
      children [
        Compass {
          name "compass_sensor"
        }
        GPS {
          name "gps_sensor"
        }
        Shape {
          appearance PBRAppearance {
            baseColor 0.333333 0.341176 0.32549
            roughness 1
          }
          geometry Cylinder {
            height 0.02
            radius 0.04
          }
        }
      ]
      name "GPS and Compass"
      boundingObject Cylinder {
        height 0.02
        radius 0.04
      }
      recognitionColors [
        0.333333 0.341176 0.32549
      ]
    }
  ]
  name "MB-01"
  boundingObject USE Body
  physics Physics {
  }
  controller "my_controller_Micael"
}
