#VRML_SIM R2023a utf8

EXTERNPROTO "https://raw.githubusercontent.com/cyberbotics/webots/R2022b/projects/objects/floors/protos/RectangleArena.proto"
EXTERNPROTO "https://raw.githubusercontent.com/cyberbotics/webots/R2022b/projects/objects/backgrounds/protos/TexturedBackground.proto"
EXTERNPROTO "https://raw.githubusercontent.com/cyberbotics/webots/R2022b/projects/objects/backgrounds/protos/TexturedBackgroundLight.proto"
EXTERNPROTO "https://raw.githubusercontent.com/cyberbotics/webots/R2023a/projects/objects/factory/containers/protos/WoodenBox.proto"

WorldInfo {
}
Viewpoint {
  orientation -0.5526309327723156 0.5767972064981445 0.6015846031267233 2.080816280720889
  position 1.481136441173882 -1.6108065378564778 28.979039705022377
}
TexturedBackground {
}
TexturedBackgroundLight {
}
RectangleArena {
  floorSize 18 18
  floorTileSize 4 4
  wallHeight 0.3
}
WoodenBox {
  size 2 2 1
}
WoodenBox {
  translation -4.5 4 0.3
  name "wooden box(1)"
  size 1 2 1
}
WoodenBox {
  translation -3.5 0.5 0.3
  name "wooden box(2)"
  size 3 1 1
}
WoodenBox {
  translation 0.5 -3.5 0.3
  name "wooden box(3)"
  size 1 1 1
}
WoodenBox {
  translation 4 2 0.3
  name "wooden box(7)"
  size 2 1 1
}
WoodenBox {
  translation 3.5 -2 0.3
  name "wooden box(8)"
  size 1 2 1
}
WoodenBox {
  translation -2.5 -2.5 0.3
  name "wooden box(4)"
  size 1 1 1
}
WoodenBox {
  translation -1 3.5 0.3
  name "wooden box(5)"
  size 4 1 1
}
WoodenBox {
  translation 2.5 -4.5 0.3
  name "wooden box(6)"
  size 1 1 1
}
Robot {
  translation -3.77453 -4.36865 0.0100056
  rotation -0.007912397385779842 0.014906679803276852 0.9998575822910241 -2.1390435657537417
  children [
    DEF Body Transform {
      translation 0 0 0.11
      children [
        Shape {
          appearance PBRAppearance {
            baseColor 0 0 1
            roughness 1
          }
          geometry Cylinder {
            height 0.2
            radius 0.15
          }
        }
      ]
      translationStep 0
      rotationStep 0
    }
    HingeJoint {
      jointParameters HingeJointParameters {
        position -3119.94347608441
        anchor 0.15 0 0.05
      }
      device [
        RotationalMotor {
          name "motor1"
        }
      ]
      endPoint Solid {
        translation 0.14103535773023002 -0.00032500677629364305 0.050024285635148956
        rotation -0.5048843362892085 0.6922176679092393 -0.5156806251975147 1.903697082721202
        children [
          DEF wheel Shape {
            appearance PBRAppearance {
              baseColor 0.1 0.1 0.1
              roughness 1
              metalness 0
            }
            geometry Cylinder {
              height 0.02
              radius 0.05
            }
          }
        ]
        boundingObject USE wheel
        physics Physics {
        }
      }
    }
    HingeJoint {
      jointParameters HingeJointParameters {
        position 8857.291370953268
        anchor -0.15 0 0.05
      }
      device [
        RotationalMotor {
          name "motor2"
        }
      ]
      endPoint Solid {
        translation -0.14108997401484236 0.00010211251136440225 0.050113326670285424
        rotation 0.31136676520170076 -0.8942845123514459 0.32141242741400894 4.601163999081326
        children [
          USE wheel
        ]
        name "solid(1)"
        boundingObject USE wheel
        physics Physics {
        }
      }
    }
    DEF Front Solid {
      translation 0 -0.13 0.21
      children [
        Shape {
          appearance PBRAppearance {
            roughness 1
          }
          geometry Box {
            size 0.02 0.04 0.01
          }
        }
      ]
      name "front"
    }
    Solid {
      translation 0.1 0.1 0.21
      rotation 0 1 0 0
      children [
        DistanceSensor {
          rotation 0 0 1 0.7854003061004253
          name "distance sensor_E_2"
          lookupTable [
            0 0 0
            3 3 0
          ]
          aperture 1
          gaussianWidth 1.57
        }
        Shape {
          geometry Cylinder {
            height 0.01
            radius 0.01
          }
        }
      ]
      name "Sensor_E_2"
    }
    Solid {
      translation -0.1 0.1 0.21
      children [
        DistanceSensor {
          rotation 0 0 1 2.3562
          name "distance sensor_D_2"
          lookupTable [
            0 0 0
            3 3 0
          ]
          aperture 1
          gaussianWidth 1.5697
        }
        Shape {
          geometry Cylinder {
            height 0.01
            radius 0.01
          }
        }
      ]
      name "Sensor_D_2"
    }
    Solid {
      translation -0.1 -0.1 0.21
      children [
        DistanceSensor {
          rotation 0 0 1 -2.355
          name "distance sensor_D_1"
          lookupTable [
            0 0 0
            3 3 0
          ]
          aperture 1
          gaussianWidth 1.57
        }
        Shape {
          geometry Cylinder {
            height 0.01
            radius 0.01
          }
        }
      ]
      name "Sensor_D_1"
    }
    Solid {
      translation 0.1 -0.1 0.21
      children [
        DistanceSensor {
          rotation 0 0 1 -0.7854
          name "distance sensor_E_1"
          lookupTable [
            0 0 0
            3 3 0
          ]
          aperture 1
          gaussianWidth 1.57
        }
        Shape {
          geometry Cylinder {
            height 0.01
            radius 0.01
          }
        }
      ]
      name "Sensor_E_1"
    }
    Solid {
      translation 1.26827e-08 4.42916e-09 0.21
      rotation 0 0 1 3.14
      children [
        Compass {
          name "compass_sensor"
        }
        GPS {
          name "gps_sensor"
        }
        Shape {
          appearance PBRAppearance {
            baseColor 0.333333 0.341176 0.32549
            roughness 1
          }
          geometry Cylinder {
            height 0.02
            radius 0.04
          }
        }
      ]
      name "GPS and Compass"
      boundingObject Cylinder {
        height 0.02
        radius 0.04
      }
      recognitionColors [
        0.333333 0.341176 0.32549
      ]
    }
  ]
  name "MB-01"
  boundingObject USE Body
  physics Physics {
  }
  controller "my_controller_Micael"
}
