#VRML_SIM R2023a utf8

EXTERNPROTO "https://raw.githubusercontent.com/cyberbotics/webots/R2022b/projects/objects/floors/protos/RectangleArena.proto"
EXTERNPROTO "https://raw.githubusercontent.com/cyberbotics/webots/R2022b/projects/objects/backgrounds/protos/TexturedBackground.proto"
EXTERNPROTO "https://raw.githubusercontent.com/cyberbotics/webots/R2022b/projects/objects/backgrounds/protos/TexturedBackgroundLight.proto"
EXTERNPROTO "https://raw.githubusercontent.com/cyberbotics/webots/R2022b/projects/objects/apartment_structure/protos/Wall.proto"
EXTERNPROTO "https://raw.githubusercontent.com/cyberbotics/webots/R2023a/projects/objects/factory/containers/protos/WoodenBox.proto"

WorldInfo {
}
Viewpoint {
  orientation -0.5657425113614702 0.5813701633932253 0.584759902827264 2.118652663753918
  position 1.0556837497919145 -0.07486646170205069 16.580539870270965
}
Wall {
  translation 0 4.5 0
  rotation -1 0 0 -5.307179586466759e-06
  size 10 0.1 1
}
TexturedBackground {
}
TexturedBackgroundLight {
}
RectangleArena {
  floorSize 10 9
  floorTileSize 2 2
  wallHeight 0.3
}
Solid {
  translation -4 2.5 0
  children [
    Shape {
      appearance PBRAppearance {
        baseColor 0 0 0
      }
      geometry Cylinder {
        height 0.01
        radius 0.1
      }
    }
  ]
}
WoodenBox {
  translation 1.5 -3 0.3
  size 1 1 1
}
WoodenBox {
  translation -2.5 1.5 0.3
  name "wooden box(1)"
  size 1 2 1
}
WoodenBox {
  translation 1.5 1 0.3
  name "wooden box(2)"
  size 1 1 1
}
Wall {
  translation 5 0 0
  rotation -1 0 0 -5.307179586466759e-06
  name "wall(4)"
  size 0.1 9 1
}
Wall {
  translation -0.5 3 0
  rotation -1 0 0 -5.307179586466759e-06
  name "wall(5)"
  size 0.1 3 1
}
Wall {
  translation -0.5 -1.88 6.36828e-07
  rotation -1 0 0 -5.307179586466759e-06
  name "wall(7)"
  size 0.1 1.8 1
}
Wall {
  translation -5 0 0
  rotation -1 0 0 -5.307179586466759e-06
  name "wall(3)"
  size 0.1 9 1
}
Wall {
  translation 0 -4.5 0
  rotation -0.8944271909999159 0.4472135954999579 0 -5.307179586466759e-06
  name "wall(1)"
  size 10 0.1 1
}
Wall {
  translation -2 -1 -5.30706e-08
  rotation -1 0 0 -5.307179586466759e-06
  name "wall(6)"
  size 6 0.1 1
}
Wall {
  translation 4 -1 -5.30706e-08
  rotation -1 0 0 -5.307179586466759e-06
  name "wall(8)"
  size 2 0.1 1
}
Robot {
  translation -4.15588 -2.73403 -0.0186537
  rotation 0.00036576532562940803 0.015622179236554113 0.999877899411537 3.051557912165195
  children [
    DEF Body Transform {
      translation 0 0 0.11
      children [
        Shape {
          appearance PBRAppearance {
            baseColor 0 0 1
            roughness 1
          }
          geometry Cylinder {
            height 0.2
            radius 0.15
          }
        }
      ]
      translationStep 0
      rotationStep 0
    }
    HingeJoint {
      jointParameters HingeJointParameters {
        position -3116.7078183827994
        anchor 0.15 0 0.05
      }
      device [
        RotationalMotor {
          name "motor1"
        }
      ]
      endPoint Solid {
        translation 0.14103535773023002 0.00032585103037898654 0.050006348441724066
        rotation 0.6484479468126437 0.42558266626689567 0.6311851190004616 2.3544459837917264
        children [
          DEF wheel Shape {
            appearance PBRAppearance {
              baseColor 0.1 0.1 0.1
              roughness 1
              metalness 0
            }
            geometry Cylinder {
              height 0.02
              radius 0.05
            }
          }
        ]
        boundingObject USE wheel
        physics Physics {
        }
      }
    }
    HingeJoint {
      jointParameters HingeJointParameters {
        position 8854.055619720637
        anchor -0.15 0 0.05
      }
      device [
        RotationalMotor {
          name "motor2"
        }
      ]
      endPoint Solid {
        translation -0.14108997401484236 -0.00011231510701721399 0.04989677589472009
        rotation 0.6789873862177953 0.2805474940804165 0.6784314504224619 2.608945235799512
        children [
          USE wheel
        ]
        name "solid(1)"
        boundingObject USE wheel
        physics Physics {
        }
      }
    }
    DEF Front Solid {
      translation 0 -0.13 0.21
      children [
        Shape {
          appearance PBRAppearance {
            roughness 1
          }
          geometry Box {
            size 0.02 0.04 0.01
          }
        }
      ]
      name "front"
    }
    Solid {
      translation 0.1 0.1 0.21
      rotation 0 1 0 0
      children [
        DistanceSensor {
          rotation 0 0 1 0.7854003061004253
          name "distance sensor_E_2"
          lookupTable [
            0 0 0
            3 3 0
          ]
          aperture 1
          gaussianWidth 1.57
        }
        Shape {
          geometry Cylinder {
            height 0.01
            radius 0.01
          }
        }
      ]
      name "Sensor_E_2"
    }
    Solid {
      translation -0.1 0.1 0.21
      children [
        DistanceSensor {
          rotation 0 0 1 2.3562
          name "distance sensor_D_2"
          lookupTable [
            0 0 0
            3 3 0
          ]
          aperture 1
          gaussianWidth 1.5697
        }
        Shape {
          geometry Cylinder {
            height 0.01
            radius 0.01
          }
        }
      ]
      name "Sensor_D_2"
    }
    Solid {
      translation -0.1 -0.1 0.21
      children [
        DistanceSensor {
          rotation 0 0 1 -2.355
          name "distance sensor_D_1"
          lookupTable [
            0 0 0
            3 3 0
          ]
          aperture 1
          gaussianWidth 1.57
        }
        Shape {
          geometry Cylinder {
            height 0.01
            radius 0.01
          }
        }
      ]
      name "Sensor_D_1"
    }
    Solid {
      translation 0.1 -0.1 0.21
      children [
        DistanceSensor {
          rotation 0 0 1 -0.7854
          name "distance sensor_E_1"
          lookupTable [
            0 0 0
            3 3 0
          ]
          aperture 1
          gaussianWidth 1.57
        }
        Shape {
          geometry Cylinder {
            height 0.01
            radius 0.01
          }
        }
      ]
      name "Sensor_E_1"
    }
    Solid {
      translation 1.26827e-08 4.42916e-09 0.21
      rotation 0 0 1 3.14
      children [
        Compass {
          name "compass_sensor"
        }
        GPS {
          name "gps_sensor"
        }
        Shape {
          appearance PBRAppearance {
            baseColor 0.333333 0.341176 0.32549
            roughness 1
          }
          geometry Cylinder {
            height 0.02
            radius 0.04
          }
        }
      ]
      name "GPS and Compass"
      boundingObject Cylinder {
        height 0.02
        radius 0.04
      }
      recognitionColors [
        0.333333 0.341176 0.32549
      ]
    }
  ]
  name "MB-01"
  boundingObject USE Body
  physics Physics {
  }
  controller "my_controller_Micael"
}
