#VRML_SIM R2023a utf8

EXTERNPROTO "https://raw.githubusercontent.com/cyberbotics/webots/R2022b/projects/objects/floors/protos/RectangleArena.proto"
EXTERNPROTO "https://raw.githubusercontent.com/cyberbotics/webots/R2022b/projects/objects/backgrounds/protos/TexturedBackground.proto"
EXTERNPROTO "https://raw.githubusercontent.com/cyberbotics/webots/R2022b/projects/objects/backgrounds/protos/TexturedBackgroundLight.proto"
EXTERNPROTO "https://raw.githubusercontent.com/cyberbotics/webots/R2022b/projects/objects/apartment_structure/protos/Wall.proto"
EXTERNPROTO "https://raw.githubusercontent.com/cyberbotics/webots/R2022b/projects/objects/factory/containers/protos/WoodenBox.proto"

WorldInfo {
}
Viewpoint {
  orientation -0.546092554794002 0.5664889068275368 0.6171492850517631 2.0639490934349825
  position 0.011965285024242565 -0.9682423556841381 7.540261380309014
}
Wall {
  translation -1.11 0 0
  rotation -1 0 0 -5.307179586466759e-06
  size 2.8 0.1 1
}
TexturedBackground {
}
TexturedBackgroundLight {
}
RectangleArena {
  floorSize 5 4.5
  floorTileSize 1 1
  wallHeight 0.3
}
Wall {
  translation -0.45 1.66 8.80955e-06
  rotation -1 0 0 -5.307179586466759e-06
  name "wall(2)"
  size 0.1 1.2 1
}
Wall {
  translation -0.45 -0.62 -3.29073e-06
  rotation -1 0 0 -5.307179586466759e-06
  name "wall(3)"
  size 0.1 1.2 1
}
Wall {
  translation 1.75 -0.01 -5.31042e-08
  rotation -1 0 0 -5.307179586466759e-06
  name "wall(1)"
  size 1.5 0.1 1
}
WoodenBox {
  translation 0.64 0.75 0.3
  size 0.5 0.5 0.5
}
WoodenBox {
  translation -1.5 -2.1 0.3
  name "wooden box(1)"
  size 0.2 0.2 0.5
}
WoodenBox {
  translation -0.74 0.64 0.3
  name "wooden box(2)"
  size 0.5 0.9 0.5
}
Robot {
  translation -1.497029815815239 -1.2007344096836992 -0.007175220288640455
  rotation 0.008202013616567295 0.01586960975847499 0.9998404284978416 2.182325719008976
  children [
    DEF Body Transform {
      translation 0 0 0.11
      children [
        Shape {
          appearance PBRAppearance {
            baseColor 0 0 1
            roughness 1
          }
          geometry Cylinder {
            height 0.2
            radius 0.15
          }
        }
      ]
      translationStep 0
      rotationStep 0
    }
    HingeJoint {
      jointParameters HingeJointParameters {
        position -3117.2045323575717
        anchor 0.15 0 0.05
      }
      device [
        RotationalMotor {
          name "motor1"
        }
      ]
      endPoint Solid {
        translation 0.14103535773023002 0.00028949826568602907 0.049850300464676235
        rotation 0.5688127091481104 0.6133208521158678 0.5479868924266827 2.050385889270344
        children [
          DEF wheel Shape {
            appearance PBRAppearance {
              baseColor 0.1 0.1 0.1
              roughness 1
              metalness 0
            }
            geometry Cylinder {
              height 0.02
              radius 0.05
            }
          }
        ]
        boundingObject USE wheel
        physics Physics {
        }
      }
    }
    HingeJoint {
      jointParameters HingeJointParameters {
        position 8854.552422463155
        anchor -0.15 0 0.05
      }
      device [
        RotationalMotor {
          name "motor2"
        }
      ]
      endPoint Solid {
        translation -0.14108997401484236 -4.9539049434897054e-05 0.04985572324596037
        rotation 0.7027654545845371 0.10188596634940812 0.7040880383188144 2.9531912833334193
        children [
          USE wheel
        ]
        name "solid(1)"
        boundingObject USE wheel
        physics Physics {
        }
      }
    }
    DEF Front Solid {
      translation 0 -0.13 0.21
      children [
        Shape {
          appearance PBRAppearance {
            roughness 1
          }
          geometry Box {
            size 0.02 0.04 0.01
          }
        }
      ]
      name "front"
    }
    Solid {
      translation 0.1 0.1 0.21
      rotation 0 1 0 0
      children [
        DistanceSensor {
          rotation 0 0 1 0.7854003061004253
          name "distance sensor_E_2"
          lookupTable [
            0 0 0
            3 3 0
          ]
          aperture 1
          gaussianWidth 1.57
        }
        Shape {
          geometry Cylinder {
            height 0.01
            radius 0.01
          }
        }
      ]
      name "Sensor_E_2"
    }
    Solid {
      translation -0.1 0.1 0.21
      children [
        DistanceSensor {
          rotation 0 0 1 2.3562
          name "distance sensor_D_2"
          lookupTable [
            0 0 0
            3 3 0
          ]
          aperture 1
          gaussianWidth 1.5697
        }
        Shape {
          geometry Cylinder {
            height 0.01
            radius 0.01
          }
        }
      ]
      name "Sensor_D_2"
    }
    Solid {
      translation -0.1 -0.1 0.21
      children [
        DistanceSensor {
          rotation 0 0 1 -2.355
          name "distance sensor_D_1"
          lookupTable [
            0 0 0
            3 3 0
          ]
          aperture 1
          gaussianWidth 1.57
        }
        Shape {
          geometry Cylinder {
            height 0.01
            radius 0.01
          }
        }
      ]
      name "Sensor_D_1"
    }
    Solid {
      translation 0.1 -0.1 0.21
      children [
        DistanceSensor {
          rotation 0 0 1 -0.7854
          name "distance sensor_E_1"
          lookupTable [
            0 0 0
            3 3 0
          ]
          aperture 1
          gaussianWidth 1.57
        }
        Shape {
          geometry Cylinder {
            height 0.01
            radius 0.01
          }
        }
      ]
      name "Sensor_E_1"
    }
    Solid {
      translation 1.26827e-08 4.42916e-09 0.21
      rotation 0 0 1 3.14
      children [
        Compass {
          name "compass_sensor"
        }
        GPS {
          name "gps_sensor"
        }
        Shape {
          appearance PBRAppearance {
            baseColor 0.333333 0.341176 0.32549
            roughness 1
          }
          geometry Cylinder {
            height 0.02
            radius 0.04
          }
        }
      ]
      name "GPS and Compass"
      boundingObject Cylinder {
        height 0.02
        radius 0.04
      }
      recognitionColors [
        0.333333 0.341176 0.32549
      ]
    }
  ]
  name "MB-01"
  boundingObject USE Body
  physics Physics {
  }
  controller "my_controller_Micael"
}
